Workbook

Sheet Instrucciones
B2: Tablero de proyectos — Websy
C4: Archivo de trabajo de Julio (administrador del área). Súbelo a Google Drive y ábrelo con Google Sheets: tiene que ser un solo link en vivo, nunca un archivo que se manda por correo. Actualizado el 30/07/2026: columnas Código, Prioridad, Plataforma y Avance de diseño, buscador de clientes y hojas de equipo editables.
B6: Cómo se usa
B7: 1 | C7: Empieza por la hoja PROYECTOS: un cliente por fila. Arriba de todo hay una BARRA DE BÚSQUEDA (celda celeste): escribe parte del nombre del cliente o su código y las filas que coinciden se resaltan. Bórrala para volver a ver todo.
B8: 2 | C8: Llena solo las celdas AMARILLAS. Las BLANCAS se calculan solas — si escribes encima, rompes la fórmula.
B9: 3 | C9: CÓDIGO es el número de cada empresa (022, 059, 065b…) y la hoja PROYECTOS va ordenada por ese número; los clientes sin código quedan al final. PRIORIDAD DISEÑO (JC) es solo la cola de Juan Carlos: 1 es el primero que diseña, y así se ordena su hoja. GRUPO se calcula solo: A = listo para producir, B = trabado por el cliente, C = no pagó o no responde.
B10: 4 | C10: PLATAFORMA (Shopify / WooCommerce / Personalizado) es lista desplegable; lo que siga en «Por definir» se pinta naranja hasta que lo completes. DEV y DISEÑADOR son distintos: Juan Carlos es el diseñador, va en TODOS los proyectos y no se cuenta como dev; los «Sin asignar» en rojo necesitan developer.
B11: 5 | C11: AVANCE DE DISEÑO (JC) es exclusiva de Juan Carlos: la marca él en su hoja y aquí se ve sola. Va de «Falta material» → «Material completo — iniciar diseño» → «Diseño en curso» → «Avance listo para presentar» → «En revisión del cliente» → «Diseño finalizado». Los devs marcan lo suyo en «Aviso del dev».
B12: 6 | C12: La hoja TABLERO se dibuja sola con lo que escribes en PROYECTOS: captura y mándasela a Luis los viernes. CHECKLISTS y REGLAS no se editan, son para consultar.
B13: Leyenda de colores
B14: Amarillo | C14: Lo llenas tú a mano.
B15: Blanco | C15: Se calcula solo. No escribir.
B16: Verde | C16: Todo en orden.
B17: Naranja | C17: Requiere que lo persigas.
B18: Rojo | C18: Urgente o congelado.
B19: Lo más importante
C20: Este archivo no obliga a nadie a nada. Las tres compuertas y los límites de trabajo los haces cumplir tú, diciendo que no. Léelas en la hoja REGLAS antes de empezar.

Sheet Proyectos
A1: BUSCAR CLIENTE → | F1: =IF($C$1="","",COUNTIF($C$4:$C$60,"*"&$C$1&"*")&" coincidencia(s)") | H1: Escribe aquí parte del nombre del cliente (o su código) y las filas que coinciden se pintan de celeste. Borra la celda para volver a ver todo. Esta hoja va ordenada por CÓDIGO; la columna Prioridad diseño solo manda la cola de Juan Carlos.
A3: Prioridad diseño (JC) | B3: Código | C3: Cliente | D3: Correo del cliente | E3: Tipo | F3: Plataforma | G3: Estado | H3: Dev | I3: Diseñador | J3: Avance de diseño (JC) | K3: Grupo | L3: Acción de hoy | M3: Pagó 50% | N3: Pagó 30% | O3: Pagó 20% | P3: Material de diseño | Q3: Plantilla productos | R3: Total productos | S3: Imágenes de Productos | T3: Cargados | U3: % cargado | V3: Qué falta exactamente | W3: Últ. respuesta | X3: Días sin responder | Y3: Notas | Z3: Aviso del dev (auto) | AA3: Nota del dev (auto) | AB3: Nota de diseño (auto)
B4: 012 | C4: LCH Graphic Equipment | E4: E-commerce | F4: Por definir | G4: Cerrado | H4: Luis | I4: Juan Carlos | J4: =IFERROR(INDEX('Juan Carlos'!$P:$P,MATCH($C4,'Juan Carlos'!$A:$A,0))&"","") | K4: =IF($C4="","",IF($M4<>"Sí","C",IF($P4="Completo","A","B"))) -> B | L4: =IF($C4="","",IF($G4="Congelado","Congelado — mensaje cada 15 días",IF(N($X4)>15,"CONGELAR HOY",IF($M4<>"Sí","COBRAR EL 50%",IF($P4<>"Completo","PERSEGUIR MATERIAL",IF(AND($G4="Desarrollo",$N4<>"Sí"),"COBRAR EL 30%",IF(AND($G4="QA + entrega",$O4<>"Sí"),"COBRAR EL 20%",IF($G4="Cola","Listo para asignar","Al día")))))))) -> CONGELAR HOY | M4: Sí | N4: Sí | O4: No | P4: Incompleto | Q4: Recibida y validada | U4: =IF(N($R4)=0,"",$T4/$R4) | V4: Nada — en revisión y ajustes de contenido post-entrega | W4: 46174 | X4: =IF($W4="","",TODAY()-$W4) -> 63 | Y4: Cliente: Luzgardo Chavez. Dev histórico: Luis. Últ. contacto de hace más de 15 días: revisar si sigue realmente al día. | Z4: =IFERROR(INDEX(Aarón!$P:$P,MATCH($C4,Aarón!$A:$A,0))&"",IFERROR(INDEX(Rubit!$P:$P,MATCH($C4,Rubit!$A:$A,0))&"",IFERROR(INDEX(Luis!$P:$P,MATCH($C4,Luis!$A:$A,0))&"",""))) | AA4: =IFERROR(INDEX(Aarón!$Q:$Q,MATCH($C4,Aarón!$A:$A,0))&"",IFERROR(INDEX(Rubit!$Q:$Q,MATCH($C4,Rubit!$A:$A,0))&"",IFERROR(INDEX(Luis!$Q:$Q,MATCH($C4,Luis!$A:$A,0))&"",""))) | AB4: =IFERROR(INDEX('Juan Carlos'!$Q:$Q,MATCH($C4,'Juan Carlos'!$A:$A,0))&"","")
B5: 019 | C5: Urban | E5: Informativa | F5: Por definir | G5: Cerrado | H5: Aarón | I5: Juan Carlos | J5: =IFERROR(INDEX('Juan Carlos'!$P:$P,MATCH($C5,'Juan Carlos'!$A:$A,0))&"","") | K5: =IF($C5="","",IF($M5<>"Sí","C",IF($P5="Completo","A","B"))) -> A | L5: =IF($C5="","",IF($G5="Congelado","Congelado — mensaje cada 15 días",IF(N($X5)>15,"CONGELAR HOY",IF($M5<>"Sí","COBRAR EL 50%",IF($P5<>"Completo","PERSEGUIR MATERIAL",IF(AND($G5="Desarrollo",$N5<>"Sí"),"COBRAR EL 30%",IF(AND($G5="QA + entrega",$O5<>"Sí"),"COBRAR EL 20%",IF($G5="Cola","Listo para asignar","Al día")))))))) -> CONGELAR HOY | M5: Sí | N5: No | O5: No | P5: Completo | Q5: No aplica | U5: =IF(N($R5)=0,"",$T5/$R5) | V5: Desarrollo | W5: 46211 | X5: =IF($W5="","",TODAY()-$W5) -> 26 | Y5: Cliente: Maria Jose. Dev histórico: Aarón. | Z5: =IFERROR(INDEX(Aarón!$P:$P,MATCH($C5,Aarón!$A:$A,0))&"",IFERROR(INDEX(Rubit!$P:$P,MATCH($C5,Rubit!$A:$A,0))&"",IFERROR(INDEX(Luis!$P:$P,MATCH($C5,Luis!$A:$A,0))&"",""))) | AA5: =IFERROR(INDEX(Aarón!$Q:$Q,MATCH($C5,Aarón!$A:$A,0))&"",IFERROR(INDEX(Rubit!$Q:$Q,MATCH($C5,Rubit!$A:$A,0))&"",IFERROR(INDEX(Luis!$Q:$Q,MATCH($C5,Luis!$A:$A,0))&"",""))) | AB5: =IFERROR(INDEX('Juan Carlos'!$Q:$Q,MATCH($C5,'Juan Carlos'!$A:$A,0))&"","")
B6: 022 | C6: By Dra. Deyanira | E6: E-commerce | F6: Por definir | G6: Cerrado | H6: Aarón | I6: Juan Carlos | J6: =IFERROR(INDEX('Juan Carlos'!$P:$P,MATCH($C6,'Juan Carlos'!$A:$A,0))&"","") | K6: =IF($C6="","",IF($M6<>"Sí","C",IF($P6="Completo","A","B"))) -> B | L6: =IF($C6="","",IF($G6="Congelado","Congelado — mensaje cada 15 días",IF(N($X6)>15,"CONGELAR HOY",IF($M6<>"Sí","COBRAR EL 50%",IF($P6<>"Completo","PERSEGUIR MATERIAL",IF(AND($G6="Desarrollo",$N6<>"Sí"),"COBRAR EL 30%",IF(AND($G6="QA + entrega",$O6<>"Sí"),"COBRAR EL 20%",IF($G6="Cola","Listo para asignar","Al día")))))))) -> CONGELAR HOY | M6: Sí | N6: Sí | O6: No | P6: Incompleto | Q6: No enviada | U6: =IF(N($R6)=0,"",$T6/$R6) | V6: Nada — entregado, en espera de comprar el hosting. Marcha blanca | W6: 46192 | X6: =IF($W6="","",TODAY()-$W6) -> 45 | Y6: Cliente: Jonathan Quiches. Dev histórico: Aarón. | Z6: =IFERROR(INDEX(Aarón!$P:$P,MATCH($C6,Aarón!$A:$A,0))&"",IFERROR(INDEX(Rubit!$P:$P,MATCH($C6,Rubit!$A:$A,0))&"",IFERROR(INDEX(Luis!$P:$P,MATCH($C6,Luis!$A:$A,0))&"",""))) | AA6: =IFERROR(INDEX(Aarón!$Q:$Q,MATCH($C6,Aarón!$A:$A,0))&"",IFERROR(INDEX(Rubit!$Q:$Q,MATCH($C6,Rubit!$A:$A,0))&"",IFERROR(INDEX(Luis!$Q:$Q,MATCH($C6,Luis!$A:$A,0))&"",""))) | AB6: =IFERROR(INDEX('Juan Carlos'!$Q:$Q,MATCH($C6,'Juan Carlos'!$A:$A,0))&"","")
B7: 026 | C7: Maginhard | E7: E-commerce | F7: Por definir | G7: Esperando material | H7: Aarón | I7: Juan Carlos | J7: =IFERROR(INDEX('Juan Carlos'!$P:$P,MATCH($C7,'Juan Carlos'!$A:$A,0))&"","") | K7: =IF($C7="","",IF($M7<>"Sí","C",IF($P7="Completo","A","B"))) -> B | L7: =IF($C7="","",IF($G7="Congelado","Congelado — mensaje cada 15 días",IF(N($X7)>15,"CONGELAR HOY",IF($M7<>"Sí","COBRAR EL 50%",IF($P7<>"Completo","PERSEGUIR MATERIAL",IF(AND($G7="Desarrollo",$N7<>"Sí"),"COBRAR EL 30%",IF(AND($G7="QA + entrega",$O7<>"Sí"),"COBRAR EL 20%",IF($G7="Cola","Listo para asignar","Al día")))))))) -> PERSEGUIR MATERIAL | M7: Sí | N7: No aplica | O7: No aplica | P7: Nada | Q7: No enviada | U7: =IF(N($R7)=0,"",$T7/$R7) | V7: Todo — BLOQUEADO: no hay acceso al grupo del cliente | X7: =IF($W7="","",TODAY()-$W7) | Y7: Cliente: Kevin. Dev histórico: Aarón. Requiere desbloquear canal de comunicación antes de nada. 30 | Z7: =IFERROR(INDEX(Aarón!$P:$P,MATCH($C7,Aarón!$A:$A,0))&"",IFERROR(INDEX(Rubit!$P:$P,MATCH($C7,Rubit!$A:$A,0))&"",IFERROR(INDEX(Luis!$P:$P,MATCH($C7,Luis!$A:$A,0))&"",""))) | AA7: =IFERROR(INDEX(Aarón!$Q:$Q,MATCH($C7,Aarón!$A:$A,0))&"",IFERROR(INDEX(Rubit!$Q:$Q,MATCH($C7,Rubit!$A:$A,0))&"",IFERROR(INDEX(Luis!$Q:$Q,MATCH($C7,Luis!$A:$A,0))&"",""))) | AB7: =IFERROR(INDEX('Juan Carlos'!$Q:$Q,MATCH($C7,'Juan Carlos'!$A:$A,0))&"","")
B8: 035 | C8: Jufrarvp S.R.L. | E8: E-commerce | F8: Por definir | G8: Congelado | H8: Aarón | I8: Juan Carlos | J8: =IFERROR(INDEX('Juan Carlos'!$P:$P,MATCH($C8,'Juan Carlos'!$A:$A,0))&"","") | K8: =IF($C8="","",IF($M8<>"Sí","C",IF($P8="Completo","A","B"))) -> A | L8: =IF($C8="","",IF($G8="Congelado","Congelado — mensaje cada 15 días",IF(N($X8)>15,"CONGELAR HOY",IF($M8<>"Sí","COBRAR EL 50%",IF($P8<>"Completo","PERSEGUIR MATERIAL",IF(AND($G8="Desarrollo",$N8<>"Sí"),"COBRAR EL 30%",IF(AND($G8="QA + entrega",$O8<>"Sí"),"COBRAR EL 20%",IF($G8="Cola","Listo para asignar","Al día")))))))) -> Congelado — mensaje cada 15 días | M8: Sí | N8: Sí | O8: No | P8: Completo | Q8: Recibida y validada | U8: =IF(N($R8)=0,"",$T8/$R8) | V8: Validación/aprobación del cliente | X8: =IF($W8="","",TODAY()-$W8) | Y8: Cliente: Julio Ponce. Sin fecha de última respuesta registrada — confirmar. | Z8: =IFERROR(INDEX(Aarón!$P:$P,MATCH($C8,Aarón!$A:$A,0))&"",IFERROR(INDEX(Rubit!$P:$P,MATCH($C8,Rubit!$A:$A,0))&"",IFERROR(INDEX(Luis!$P:$P,MATCH($C8,Luis!$A:$A,0))&"",""))) | AA8: =IFERROR(INDEX(Aarón!$Q:$Q,MATCH($C8,Aarón!$A:$A,0))&"",IFERROR(INDEX(Rubit!$Q:$Q,MATCH($C8,Rubit!$A:$A,0))&"",IFERROR(INDEX(Luis!$Q:$Q,MATCH($C8,Luis!$A:$A,0))&"",""))) | AB8: =IFERROR(INDEX('Juan Carlos'!$Q:$Q,MATCH($C8,'Juan Carlos'!$A:$A,0))&"","")
B9: 036 | C9: Soluz | E9: E-commerce | F9: Por definir | G9: Desarrollo | H9: Aarón | I9: Juan Carlos | J9: =IFERROR(INDEX('Juan Carlos'!$P:$P,MATCH($C9,'Juan Carlos'!$A:$A,0))&"","") -> Diseño finalizado | K9: =IF($C9="","",IF($M9<>"Sí","C",IF($P9="Completo","A","B"))) -> A | L9: =IF($C9="","",IF($G9="Congelado","Congelado — mensaje cada 15 días",IF(N($X9)>15,"CONGELAR HOY",IF($M9<>"Sí","COBRAR EL 50%",IF($P9<>"Completo","PERSEGUIR MATERIAL",IF(AND($G9="Desarrollo",$N9<>"Sí"),"COBRAR EL 30%",IF(AND($G9="QA + entrega",$O9<>"Sí"),"COBRAR EL 20%",IF($G9="Cola","Listo para asignar","Al día")))))))) -> CONGELAR HOY | M9: Sí | N9: Sí | O9: No | P9: Completo | Q9: No enviada | U9: =IF(N($R9)=0,"",$T9/$R9) | V9: Reunión reprogramada + validación del cliente sobre carga de productos | W9: 46213 | X9: =IF($W9="","",TODAY()-$W9) -> 24 | Y9: Cliente: Giancarlo Rosario. En transición de Aarón a Luis (aún no formalizada). | Z9: =IFERROR(INDEX(Aarón!$P:$P,MATCH($C9,Aarón!$A:$A,0))&"",IFERROR(INDEX(Rubit!$P:$P,MATCH($C9,Rubit!$A:$A,0))&"",IFERROR(INDEX(Luis!$P:$P,MATCH($C9,Luis!$A:$A,0))&"",""))) | AA9: =IFERROR(INDEX(Aarón!$Q:$Q,MATCH($C9,Aarón!$A:$A,0))&"",IFERROR(INDEX(Rubit!$Q:$Q,MATCH($C9,Rubit!$A:$A,0))&"",IFERROR(INDEX(Luis!$Q:$Q,MATCH($C9,Luis!$A:$A,0))&"",""))) | AB9: =IFERROR(INDEX('Juan Carlos'!$Q:$Q,MATCH($C9,'Juan Carlos'!$A:$A,0))&"","")
B10: 038 | C10: L'Andrea's Secret | E10: E-commerce | F10: Por definir | G10: Esperando material | H10: Luis | I10: Juan Carlos | J10: =IFERROR(INDEX('Juan Carlos'!$P:$P,MATCH($C10,'Juan Carlos'!$A:$A,0))&"","") -> Material completo — iniciar diseño | K10: =IF($C10="","",IF($M10<>"Sí","C",IF($P10="Completo","A","B"))) -> A | L10: =IF($C10="","",IF($G10="Congelado","Congelado — mensaje cada 15 días",IF(N($X10)>15,"CONGELAR HOY",IF($M10<>"Sí","COBRAR EL 50%",IF($P10<>"Completo","PERSEGUIR MATERIAL",IF(AND($G10="Desarrollo",$N10<>"Sí"),"COBRAR EL 30%",IF(AND($G10="QA + entrega",$O10<>"Sí"),"COBRAR EL 20%",IF($G10="Cola","Listo para asignar","Al día")))))))) -> Al día | M10: Sí | N10: Sí | O10: No | P10: Completo | Q10: Recibida con errores | U10: =IF(N($R10)=0,"",$T10/$R10) | V10: Material de diseño — brief llenado | X10: =IF($W10="","",TODAY()-$W10) | Y10: Cliente: Gladys Poma. Dev histórico: Luis. 30% ya pagado según pizarra. | Z10: =IFERROR(INDEX(Aarón!$P:$P,MATCH($C10,Aarón!$A:$A,0))&"",IFERROR(INDEX(Rubit!$P:$P,MATCH($C10,Rubit!$A:$A,0))&"",IFERROR(INDEX(Luis!$P:$P,MATCH($C10,Luis!$A:$A,0))&"",""))) | AA10: =IFERROR(INDEX(Aarón!$Q:$Q,MATCH($C10,Aarón!$A:$A,0))&"",IFERROR(INDEX(Rubit!$Q:$Q,MATCH($C10,Rubit!$A:$A,0))&"",IFERROR(INDEX(Luis!$Q:$Q,MATCH($C10,Luis!$A:$A,0))&"",""))) | AB10: =IFERROR(INDEX('Juan Carlos'!$Q:$Q,MATCH($C10,'Juan Carlos'!$A:$A,0))&"","")
B11: 040 | C11: Maquinarias Aoxiang | E11: E-commerce | F11: Por definir | G11: Cerrado | H11: Aarón | I11: Juan Carlos | J11: =IFERROR(INDEX('Juan Carlos'!$P:$P,MATCH($C11,'Juan Carlos'!$A:$A,0))&"","") -> Diseño finalizado | K11: =IF($C11="","",IF($M11<>"Sí","C",IF($P11="Completo","A","B"))) -> A | L11: =IF($C11="","",IF($G11="Congelado","Congelado — mensaje cada 15 días",IF(N($X11)>15,"CONGELAR HOY",IF($M11<>"Sí","COBRAR EL 50%",IF($P11<>"Completo","PERSEGUIR MATERIAL",IF(AND($G11="Desarrollo",$N11<>"Sí"),"COBRAR EL 30%",IF(AND($G11="QA + entrega",$O11<>"Sí"),"COBRAR EL 20%",IF($G11="Cola","Listo para asignar","Al día")))))))) -> CONGELAR HOY | M11: Sí | N11: Sí | O11: Sí | P11: Completo | Q11: Recibida con errores | U11: =IF(N($R11)=0,"",$T11/$R11) | V11: Nada — diseño aprobado | W11: 46200 | X11: =IF($W11="","",TODAY()-$W11) -> 37 | Y11: Cliente: Liliana y Javier. | Z11: =IFERROR(INDEX(Aarón!$P:$P,MATCH($C11,Aarón!$A:$A,0))&"",IFERROR(INDEX(Rubit!$P:$P,MATCH($C11,Rubit!$A:$A,0))&"",IFERROR(INDEX(Luis!$P:$P,MATCH($C11,Luis!$A:$A,0))&"",""))) | AA11: =IFERROR(INDEX(Aarón!$Q:$Q,MATCH($C11,Aarón!$A:$A,0))&"",IFERROR(INDEX(Rubit!$Q:$Q,MATCH($C11,Rubit!$A:$A,0))&"",IFERROR(INDEX(Luis!$Q:$Q,MATCH($C11,Luis!$A:$A,0))&"",""))) | AB11: =IFERROR(INDEX('Juan Carlos'!$Q:$Q,MATCH($C11,'Juan Carlos'!$A:$A,0))&"","")
B12: 041 | C12: Place For Pet | E12: E-commerce | F12: Por definir | G12: Congelado | H12: Rubit | I12: Juan Carlos | J12: =IFERROR(INDEX('Juan Carlos'!$P:$P,MATCH($C12,'Juan Carlos'!$A:$A,0))&"","") | K12: =IF($C12="","",IF($M12<>"Sí","C",IF($P12="Completo","A","B"))) -> A | L12: =IF($C12="","",IF($G12="Congelado","Congelado — mensaje cada 15 días",IF(N($X12)>15,"CONGELAR HOY",IF($M12<>"Sí","COBRAR EL 50%",IF($P12<>"Completo","PERSEGUIR MATERIAL",IF(AND($G12="Desarrollo",$N12<>"Sí"),"COBRAR EL 30%",IF(AND($G12="QA + entrega",$O12<>"Sí"),"COBRAR EL 20%",IF($G12="Cola","Listo para asignar","Al día")))))))) -> Congelado — mensaje cada 15 días | M12: Sí | N12: Sí | O12: Sí | P12: Completo | Q12: Recibida con errores | U12: =IF(N($R12)=0,"",$T12/$R12) | V12: Reunión agendada | W12: 46216 | X12: =IF($W12="","",TODAY()-$W12) -> 21 | Y12: Cliente: Natasha Marval y Vanessa Ayvar. Dev histórico: Rubit. - Perseguir material a partir del 5/08 | Z12: =IFERROR(INDEX(Aarón!$P:$P,MATCH($C12,Aarón!$A:$A,0))&"",IFERROR(INDEX(Rubit!$P:$P,MATCH($C12,Rubit!$A:$A,0))&"",IFERROR(INDEX(Luis!$P:$P,MATCH($C12,Luis!$A:$A,0))&"",""))) | AA12: =IFERROR(INDEX(Aarón!$Q:$Q,MATCH($C12,Aarón!$A:$A,0))&"",IFERROR(INDEX(Rubit!$Q:$Q,MATCH($C12,Rubit!$A:$A,0))&"",IFERROR(INDEX(Luis!$Q:$Q,MATCH($C12,Luis!$A:$A,0))&"",""))) | AB12: =IFERROR(INDEX('Juan Carlos'!$Q:$Q,MATCH($C12,'Juan Carlos'!$A:$A,0))&"","")
A13: 9 | B13: 051 | C13: Dr. Gonzalo Caballero | E13: Informativa | F13: Por definir | G13: Esperando material | H13: Sin asignar | I13: Juan Carlos | J13: =IFERROR(INDEX('Juan Carlos'!$P:$P,MATCH($C13,'Juan Carlos'!$A:$A,0))&"","") | K13: =IF($C13="","",IF($M13<>"Sí","C",IF($P13="Completo","A","B"))) -> B | L13: =IF($C13="","",IF($G13="Congelado","Congelado — mensaje cada 15 días",IF(N($X13)>15,"CONGELAR HOY",IF($M13<>"Sí","COBRAR EL 50%",IF($P13<>"Completo","PERSEGUIR MATERIAL",IF(AND($G13="Desarrollo",$N13<>"Sí"),"COBRAR EL 30%",IF(AND($G13="QA + entrega",$O13<>"Sí"),"COBRAR EL 20%",IF($G13="Cola","Listo para asignar","Al día")))))))) -> CONGELAR HOY | M13: Sí | N13: No aplica | O13: No aplica | P13: Incompleto | Q13: No aplica | U13: =IF(N($R13)=0,"",$T13/$R13) | V13: Toda la información del cliente — aún no ha entregado nada | W13: 46210 | X13: =IF($W13="","",TODAY()-$W13) -> 27 | Y13: Cliente: Gonzalo Caballero. 30% marcado como 'en camino'. | Z13: =IFERROR(INDEX(Aarón!$P:$P,MATCH($C13,Aarón!$A:$A,0))&"",IFERROR(INDEX(Rubit!$P:$P,MATCH($C13,Rubit!$A:$A,0))&"",IFERROR(INDEX(Luis!$P:$P,MATCH($C13,Luis!$A:$A,0))&"",""))) | AA13: =IFERROR(INDEX(Aarón!$Q:$Q,MATCH($C13,Aarón!$A:$A,0))&"",IFERROR(INDEX(Rubit!$Q:$Q,MATCH($C13,Rubit!$A:$A,0))&"",IFERROR(INDEX(Luis!$Q:$Q,MATCH($C13,Luis!$A:$A,0))&"",""))) | AB13: =IFERROR(INDEX('Juan Carlos'!$Q:$Q,MATCH($C13,'Juan Carlos'!$A:$A,0))&"","")
B14: 053 | C14: Youbi Importaciones | E14: Informativa | F14: Por definir | G14: Desarrollo | H14: Aarón | I14: Juan Carlos | J14: =IFERROR(INDEX('Juan Carlos'!$P:$P,MATCH($C14,'Juan Carlos'!$A:$A,0))&"","") -> Diseño finalizado | K14: =IF($C14="","",IF($M14<>"Sí","C",IF($P14="Completo","A","B"))) -> A | L14: =IF($C14="","",IF($G14="Congelado","Congelado — mensaje cada 15 días",IF(N($X14)>15,"CONGELAR HOY",IF($M14<>"Sí","COBRAR EL 50%",IF($P14<>"Completo","PERSEGUIR MATERIAL",IF(AND($G14="Desarrollo",$N14<>"Sí"),"COBRAR EL 30%",IF(AND($G14="QA + entrega",$O14<>"Sí"),"COBRAR EL 20%",IF($G14="Cola","Listo para asignar","Al día")))))))) -> CONGELAR HOY | M14: Sí | N14: No | O14: No | P14: Completo | Q14: No aplica | U14: =IF(N($R14)=0,"",$T14/$R14) | V14: Validación de diseño en paralelo al desarrollo | W14: 46212 | X14: =IF($W14="","",TODAY()-$W14) -> 25 | Y14: Cliente: Jenifer y Jorge. 30% pagado. | Z14: =IFERROR(INDEX(Aarón!$P:$P,MATCH($C14,Aarón!$A:$A,0))&"",IFERROR(INDEX(Rubit!$P:$P,MATCH($C14,Rubit!$A:$A,0))&"",IFERROR(INDEX(Luis!$P:$P,MATCH($C14,Luis!$A:$A,0))&"",""))) | AA14: =IFERROR(INDEX(Aarón!$Q:$Q,MATCH($C14,Aarón!$A:$A,0))&"",IFERROR(INDEX(Rubit!$Q:$Q,MATCH($C14,Rubit!$A:$A,0))&"",IFERROR(INDEX(Luis!$Q:$Q,MATCH($C14,Luis!$A:$A,0))&"",""))) | AB14: =IFERROR(INDEX('Juan Carlos'!$Q:$Q,MATCH($C14,'Juan Carlos'!$A:$A,0))&"","")
B15: 054 | C15: Ale Bakery | E15: Informativa | F15: WooCommerce | G15: Cerrado | H15: Rubit | I15: Juan Carlos | J15: =IFERROR(INDEX('Juan Carlos'!$P:$P,MATCH($C15,'Juan Carlos'!$A:$A,0))&"","") | K15: =IF($C15="","",IF($M15<>"Sí","C",IF($P15="Completo","A","B"))) -> A | L15: =IF($C15="","",IF($G15="Congelado","Congelado — mensaje cada 15 días",IF(N($X15)>15,"CONGELAR HOY",IF($M15<>"Sí","COBRAR EL 50%",IF($P15<>"Completo","PERSEGUIR MATERIAL",IF(AND($G15="Desarrollo",$N15<>"Sí"),"COBRAR EL 30%",IF(AND($G15="QA + entrega",$O15<>"Sí"),"COBRAR EL 20%",IF($G15="Cola","Listo para asignar","Al día")))))))) -> CONGELAR HOY | M15: Sí | N15: Sí | O15: Sí | P15: Completo | Q15: No aplica | U15: =IF(N($R15)=0,"",$T15/$R15) | V15: Fotografías finales del cliente para completar el diseño (30% ya pagado) | W15: 46219 | X15: =IF($W15="","",TODAY()-$W15) -> 18 | Y15: Cliente: Alejandro y Alejandra. Dev histórico: Rubit. Cita viernes 24/07 . Finalizado , agendar reunion final 5 dias antes de su ultima cita | Z15: =IFERROR(INDEX(Aarón!$P:$P,MATCH($C15,Aarón!$A:$A,0))&"",IFERROR(INDEX(Rubit!$P:$P,MATCH($C15,Rubit!$A:$A,0))&"",IFERROR(INDEX(Luis!$P:$P,MATCH($C15,Luis!$A:$A,0))&"",""))) | AA15: =IFERROR(INDEX(Aarón!$Q:$Q,MATCH($C15,Aarón!$A:$A,0))&"",IFERROR(INDEX(Rubit!$Q:$Q,MATCH($C15,Rubit!$A:$A,0))&"",IFERROR(INDEX(Luis!$Q:$Q,MATCH($C15,Luis!$A:$A,0))&"",""))) | AB15: =IFERROR(INDEX('Juan Carlos'!$Q:$Q,MATCH($C15,'Juan Carlos'!$A:$A,0))&"","")
B16: 055 | C16: Anahir Store | E16: E-commerce | F16: Por definir | G16: Diseño | H16: Rubit | I16: Juan Carlos | J16: =IFERROR(INDEX('Juan Carlos'!$P:$P,MATCH($C16,'Juan Carlos'!$A:$A,0))&"","") | K16: =IF($C16="","",IF($M16<>"Sí","C",IF($P16="Completo","A","B"))) -> B | L16: =IF($C16="","",IF($G16="Congelado","Congelado — mensaje cada 15 días",IF(N($X16)>15,"CONGELAR HOY",IF($M16<>"Sí","COBRAR EL 50%",IF($P16<>"Completo","PERSEGUIR MATERIAL",IF(AND($G16="Desarrollo",$N16<>"Sí"),"COBRAR EL 30%",IF(AND($G16="QA + entrega",$O16<>"Sí"),"COBRAR EL 20%",IF($G16="Cola","Listo para asignar","Al día")))))))) -> CONGELAR HOY | M16: Sí | N16: Sí | O16: No aplica | P16: Incompleto | Q16: No aplica | R16: 100 | U16: =IF(N($R16)=0,"",$T16/$R16) -> 0 | V16: Feedback/aprobación del diseño (30% ya pagado) | W16: 46212 | X16: =IF($W16="","",TODAY()-$W16) -> 25 | Y16: Cliente: Norma Gonzales. Dev histórico: Rubit. | Z16: =IFERROR(INDEX(Aarón!$P:$P,MATCH($C16,Aarón!$A:$A,0))&"",IFERROR(INDEX(Rubit!$P:$P,MATCH($C16,Rubit!$A:$A,0))&"",IFERROR(INDEX(Luis!$P:$P,MATCH($C16,Luis!$A:$A,0))&"",""))) | AA16: =IFERROR(INDEX(Aarón!$Q:$Q,MATCH($C16,Aarón!$A:$A,0))&"",IFERROR(INDEX(Rubit!$Q:$Q,MATCH($C16,Rubit!$A:$A,0))&"",IFERROR(INDEX(Luis!$Q:$Q,MATCH($C16,Luis!$A:$A,0))&"",""))) | AB16: =IFERROR(INDEX('Juan Carlos'!$Q:$Q,MATCH($C16,'Juan Carlos'!$A:$A,0))&"","")
B17: 056 | C17: Perforaciones H&A | E17: Informativa | F17: Por definir | G17: Cerrado | H17: Sin asignar | I17: Juan Carlos | J17: =IFERROR(INDEX('Juan Carlos'!$P:$P,MATCH($C17,'Juan Carlos'!$A:$A,0))&"","") | K17: =IF($C17="","",IF($M17<>"Sí","C",IF($P17="Completo","A","B"))) -> A | L17: =IF($C17="","",IF($G17="Congelado","Congelado — mensaje cada 15 días",IF(N($X17)>15,"CONGELAR HOY",IF($M17<>"Sí","COBRAR EL 50%",IF($P17<>"Completo","PERSEGUIR MATERIAL",IF(AND($G17="Desarrollo",$N17<>"Sí"),"COBRAR EL 30%",IF(AND($G17="QA + entrega",$O17<>"Sí"),"COBRAR EL 20%",IF($G17="Cola","Listo para asignar","Al día")))))))) -> CONGELAR HOY | M17: Sí | N17: Sí | O17: Sí | P17: Completo | Q17: No aplica | U17: =IF(N($R17)=0,"",$T17/$R17) | V17: Nada pendiente de diseño — falta confirmar developer asignado | W17: 46218 | X17: =IF($W17="","",TODAY()-$W17) -> 19 | Y17: Cliente: Jessenia Lizbeth. Diseño aprobado, sin developer confirmado. | Z17: =IFERROR(INDEX(Aarón!$P:$P,MATCH($C17,Aarón!$A:$A,0))&"",IFERROR(INDEX(Rubit!$P:$P,MATCH($C17,Rubit!$A:$A,0))&"",IFERROR(INDEX(Luis!$P:$P,MATCH($C17,Luis!$A:$A,0))&"",""))) | AA17: =IFERROR(INDEX(Aarón!$Q:$Q,MATCH($C17,Aarón!$A:$A,0))&"",IFERROR(INDEX(Rubit!$Q:$Q,MATCH($C17,Rubit!$A:$A,0))&"",IFERROR(INDEX(Luis!$Q:$Q,MATCH($C17,Luis!$A:$A,0))&"",""))) | AB17: =IFERROR(INDEX('Juan Carlos'!$Q:$Q,MATCH($C17,'Juan Carlos'!$A:$A,0))&"","")
B18: 057 | C18: Grúas Sagitario | E18: Informativa | F18: Por definir | G18: Diseño | H18: Luis | I18: Juan Carlos | J18: =IFERROR(INDEX('Juan Carlos'!$P:$P,MATCH($C18,'Juan Carlos'!$A:$A,0))&"","") | K18: =IF($C18="","",IF($M18<>"Sí","C",IF($P18="Completo","A","B"))) -> B | L18: =IF($C18="","",IF($G18="Congelado","Congelado — mensaje cada 15 días",IF(N($X18)>15,"CONGELAR HOY",IF($M18<>"Sí","COBRAR EL 50%",IF($P18<>"Completo","PERSEGUIR MATERIAL",IF(AND($G18="Desarrollo",$N18<>"Sí"),"COBRAR EL 30%",IF(AND($G18="QA + entrega",$O18<>"Sí"),"COBRAR EL 20%",IF($G18="Cola","Listo para asignar","Al día")))))))) -> CONGELAR HOY | M18: Sí | N18: No aplica | O18: No aplica | P18: Incompleto | Q18: No aplica | U18: =IF(N($R18)=0,"",$T18/$R18) | V18: Aprobación del diseño por parte del cliente | W18: 46218 | X18: =IF($W18="","",TODAY()-$W18) -> 19 | Y18: Cliente: J Pino. | Z18: =IFERROR(INDEX(Aarón!$P:$P,MATCH($C18,Aarón!$A:$A,0))&"",IFERROR(INDEX(Rubit!$P:$P,MATCH($C18,Rubit!$A:$A,0))&"",IFERROR(INDEX(Luis!$P:$P,MATCH($C18,Luis!$A:$A,0))&"",""))) | AA18: =IFERROR(INDEX(Aarón!$Q:$Q,MATCH($C18,Aarón!$A:$A,0))&"",IFERROR(INDEX(Rubit!$Q:$Q,MATCH($C18,Rubit!$A:$A,0))&"",IFERROR(INDEX(Luis!$Q:$Q,MATCH($C18,Luis!$A:$A,0))&"",""))) | AB18: =IFERROR(INDEX('Juan Carlos'!$Q:$Q,MATCH($C18,'Juan Carlos'!$A:$A,0))&"","")
B19: 059 | C19: Los Halcones | E19: E-commerce | F19: Por definir | G19: Desarrollo | H19: Aarón | I19: Juan Carlos | J19: =IFERROR(INDEX('Juan Carlos'!$P:$P,MATCH($C19,'Juan Carlos'!$A:$A,0))&"","") -> Diseño finalizado | K19: =IF($C19="","",IF($M19<>"Sí","C",IF($P19="Completo","A","B"))) -> A | L19: =IF($C19="","",IF($G19="Congelado","Congelado — mensaje cada 15 días",IF(N($X19)>15,"CONGELAR HOY",IF($M19<>"Sí","COBRAR EL 50%",IF($P19<>"Completo","PERSEGUIR MATERIAL",IF(AND($G19="Desarrollo",$N19<>"Sí"),"COBRAR EL 30%",IF(AND($G19="QA + entrega",$O19<>"Sí"),"COBRAR EL 20%",IF($G19="Cola","Listo para asignar","Al día")))))))) -> CONGELAR HOY | M19: Sí | N19: Sí | O19: Sí | P19: Completo | Q19: No aplica | R19: 0 | S19: Si- NO - INCOMPLETO | T19: 0 | U19: =IF(N($R19)=0,"",$T19/$R19) | V19: Nada — en implementación, cliente informado y disponible | W19: 46218 | X19: =IF($W19="","",TODAY()-$W19) -> 19 | Y19: Cliente: Juan. - Cita viernes 24-07 | Z19: =IFERROR(INDEX(Aarón!$P:$P,MATCH($C19,Aarón!$A:$A,0))&"",IFERROR(INDEX(Rubit!$P:$P,MATCH($C19,Rubit!$A:$A,0))&"",IFERROR(INDEX(Luis!$P:$P,MATCH($C19,Luis!$A:$A,0))&"",""))) | AA19: =IFERROR(INDEX(Aarón!$Q:$Q,MATCH($C19,Aarón!$A:$A,0))&"",IFERROR(INDEX(Rubit!$Q:$Q,MATCH($C19,Rubit!$A:$A,0))&"",IFERROR(INDEX(Luis!$Q:$Q,MATCH($C19,Luis!$A:$A,0))&"",""))) | AB19: =IFERROR(INDEX('Juan Carlos'!$Q:$Q,MATCH($C19,'Juan Carlos'!$A:$A,0))&"","")
B20: 061 | C20: Comsavitar SAC | E20: E-commerce | F20: Por definir | G20: Diseño | H20: Sin asignar | I20: Juan Carlos | J20: =IFERROR(INDEX('Juan Carlos'!$P:$P,MATCH($C20,'Juan Carlos'!$A:$A,0))&"","") | K20: =IF($C20="","",IF($M20<>"Sí","C",IF($P20="Completo","A","B"))) -> B | L20: =IF($C20="","",IF($G20="Congelado","Congelado — mensaje cada 15 días",IF(N($X20)>15,"CONGELAR HOY",IF($M20<>"Sí","COBRAR EL 50%",IF($P20<>"Completo","PERSEGUIR MATERIAL",IF(AND($G20="Desarrollo",$N20<>"Sí"),"COBRAR EL 30%",IF(AND($G20="QA + entrega",$O20<>"Sí"),"COBRAR EL 20%",IF($G20="Cola","Listo para asignar","Al día")))))))) -> CONGELAR HOY | M20: Sí | N20: No aplica | O20: No aplica | P20: Incompleto | Q20: No aplica | U20: =IF(N($R20)=0,"",$T20/$R20) | V20: Validación final del manual de marca | W20: 46218 | X20: =IF($W20="","",TODAY()-$W20) -> 19 | Y20: Cliente: Katia. PENDIENTE: agendar la reunión de brief. | Z20: =IFERROR(INDEX(Aarón!$P:$P,MATCH($C20,Aarón!$A:$A,0))&"",IFERROR(INDEX(Rubit!$P:$P,MATCH($C20,Rubit!$A:$A,0))&"",IFERROR(INDEX(Luis!$P:$P,MATCH($C20,Luis!$A:$A,0))&"",""))) | AA20: =IFERROR(INDEX(Aarón!$Q:$Q,MATCH($C20,Aarón!$A:$A,0))&"",IFERROR(INDEX(Rubit!$Q:$Q,MATCH($C20,Rubit!$A:$A,0))&"",IFERROR(INDEX(Luis!$Q:$Q,MATCH($C20,Luis!$A:$A,0))&"",""))) | AB20: =IFERROR(INDEX('Juan Carlos'!$Q:$Q,MATCH($C20,'Juan Carlos'!$A:$A,0))&"","")
A21: 1 | B21: 062 | C21: I&N Caprimoda | E21: E-commerce | F21: Por definir | G21: QA + entrega | H21: Sin asignar | I21: Juan Carlos | J21: =IFERROR(INDEX('Juan Carlos'!$P:$P,MATCH($C21,'Juan Carlos'!$A:$A,0))&"","") -> Diseño finalizado | K21: =IF($C21="","",IF($M21<>"Sí","C",IF($P21="Completo","A","B"))) -> A | L21: =IF($C21="","",IF($G21="Congelado","Congelado — mensaje cada 15 días",IF(N($X21)>15,"CONGELAR HOY",IF($M21<>"Sí","COBRAR EL 50%",IF($P21<>"Completo","PERSEGUIR MATERIAL",IF(AND($G21="Desarrollo",$N21<>"Sí"),"COBRAR EL 30%",IF(AND($G21="QA + entrega",$O21<>"Sí"),"COBRAR EL 20%",IF($G21="Cola","Listo para asignar","Al día")))))))) -> CONGELAR HOY | M21: Sí | N21: No | O21: No | P21: Completo | Q21: No enviada | U21: =IF(N($R21)=0,"",$T21/$R21) | V21: Carga y validación de contenidos | W21: 46218 | X21: =IF($W21="","",TODAY()-$W21) -> 19 | Y21: Cliente: Noelia Juanfer. OJO: Luis tiene capacidad 0 según Reglas — confirmar si esto es correcto. Cita viernes 24/07 | Z21: =IFERROR(INDEX(Aarón!$P:$P,MATCH($C21,Aarón!$A:$A,0))&"",IFERROR(INDEX(Rubit!$P:$P,MATCH($C21,Rubit!$A:$A,0))&"",IFERROR(INDEX(Luis!$P:$P,MATCH($C21,Luis!$A:$A,0))&"",""))) | AA21: =IFERROR(INDEX(Aarón!$Q:$Q,MATCH($C21,Aarón!$A:$A,0))&"",IFERROR(INDEX(Rubit!$Q:$Q,MATCH($C21,Rubit!$A:$A,0))&"",IFERROR(INDEX(Luis!$Q:$Q,MATCH($C21,Luis!$A:$A,0))&"",""))) | AB21: =IFERROR(INDEX('Juan Carlos'!$Q:$Q,MATCH($C21,'Juan Carlos'!$A:$A,0))&"","")
B22: 064 | C22: Eviext | E22: Informativa | F22: Por definir | G22: Desarrollo | H22: Sin asignar | I22: Juan Carlos | J22: =IFERROR(INDEX('Juan Carlos'!$P:$P,MATCH($C22,'Juan Carlos'!$A:$A,0))&"","") -> Diseño finalizado | K22: =IF($C22="","",IF($M22<>"Sí","C",IF($P22="Completo","A","B"))) -> A | L22: =IF($C22="","",IF($G22="Congelado","Congelado — mensaje cada 15 días",IF(N($X22)>15,"CONGELAR HOY",IF($M22<>"Sí","COBRAR EL 50%",IF($P22<>"Completo","PERSEGUIR MATERIAL",IF(AND($G22="Desarrollo",$N22<>"Sí"),"COBRAR EL 30%",IF(AND($G22="QA + entrega",$O22<>"Sí"),"COBRAR EL 20%",IF($G22="Cola","Listo para asignar","Al día")))))))) -> CONGELAR HOY | M22: Sí | N22: Sí | O22: No | P22: Completo | Q22: No aplica | U22: =IF(N($R22)=0,"",$T22/$R22) | V22: Integración de contenidos finales del cliente | W22: 46219 | X22: =IF($W22="","",TODAY()-$W22) -> 18 | Y22: Cliente: Reina. 30% en camino/confirmado. Sin developer confirmado — asignar. | Z22: =IFERROR(INDEX(Aarón!$P:$P,MATCH($C22,Aarón!$A:$A,0))&"",IFERROR(INDEX(Rubit!$P:$P,MATCH($C22,Rubit!$A:$A,0))&"",IFERROR(INDEX(Luis!$P:$P,MATCH($C22,Luis!$A:$A,0))&"",""))) | AA22: =IFERROR(INDEX(Aarón!$Q:$Q,MATCH($C22,Aarón!$A:$A,0))&"",IFERROR(INDEX(Rubit!$Q:$Q,MATCH($C22,Rubit!$A:$A,0))&"",IFERROR(INDEX(Luis!$Q:$Q,MATCH($C22,Luis!$A:$A,0))&"",""))) | AB22: =IFERROR(INDEX('Juan Carlos'!$Q:$Q,MATCH($C22,'Juan Carlos'!$A:$A,0))&"","")
B23: 065 | C23: Azcecorp | E23: E-commerce | F23: Por definir | G23: Desarrollo | H23: Sin asignar | I23: Juan Carlos | J23: =IFERROR(INDEX('Juan Carlos'!$P:$P,MATCH($C23,'Juan Carlos'!$A:$A,0))&"","") | K23: =IF($C23="","",IF($M23<>"Sí","C",IF($P23="Completo","A","B"))) -> B | L23: =IF($C23="","",IF($G23="Congelado","Congelado — mensaje cada 15 días",IF(N($X23)>15,"CONGELAR HOY",IF($M23<>"Sí","COBRAR EL 50%",IF($P23<>"Completo","PERSEGUIR MATERIAL",IF(AND($G23="Desarrollo",$N23<>"Sí"),"COBRAR EL 30%",IF(AND($G23="QA + entrega",$O23<>"Sí"),"COBRAR EL 20%",IF($G23="Cola","Listo para asignar","Al día")))))))) -> CONGELAR HOY | M23: Sí | N23: Sí | O23: No aplica | P23: Incompleto | Q23: Recibida con errores | U23: =IF(N($R23)=0,"",$T23/$R23) | V23: Validar catálogos y completar precios/datos finales antes de maquetar | W23: 46218 | X23: =IF($W23="","",TODAY()-$W23) -> 19 | Y23: Cliente: Alex Cordoba. Responsable actual 'Admin' — no es developer de código, reasignar a Aarón/Rubit/Luis. | Z23: =IFERROR(INDEX(Aarón!$P:$P,MATCH($C23,Aarón!$A:$A,0))&"",IFERROR(INDEX(Rubit!$P:$P,MATCH($C23,Rubit!$A:$A,0))&"",IFERROR(INDEX(Luis!$P:$P,MATCH($C23,Luis!$A:$A,0))&"",""))) | AA23: =IFERROR(INDEX(Aarón!$Q:$Q,MATCH($C23,Aarón!$A:$A,0))&"",IFERROR(INDEX(Rubit!$Q:$Q,MATCH($C23,Rubit!$A:$A,0))&"",IFERROR(INDEX(Luis!$Q:$Q,MATCH($C23,Luis!$A:$A,0))&"",""))) | AB23: =IFERROR(INDEX('Juan Carlos'!$Q:$Q,MATCH($C23,'Juan Carlos'!$A:$A,0))&"","")
B24: 065b | C24: Karol Milena Añez | E24: E-commerce | F24: Por definir | G24: Esperando material | H24: Rubit | I24: Juan Carlos | J24: =IFERROR(INDEX('Juan Carlos'!$P:$P,MATCH($C24,'Juan Carlos'!$A:$A,0))&"","") | K24: =IF($C24="","",IF($M24<>"Sí","C",IF($P24="Completo","A","B"))) -> B | L24: =IF($C24="","",IF($G24="Congelado","Congelado — mensaje cada 15 días",IF(N($X24)>15,"CONGELAR HOY",IF($M24<>"Sí","COBRAR EL 50%",IF($P24<>"Completo","PERSEGUIR MATERIAL",IF(AND($G24="Desarrollo",$N24<>"Sí"),"COBRAR EL 30%",IF(AND($G24="QA + entrega",$O24<>"Sí"),"COBRAR EL 20%",IF($G24="Cola","Listo para asignar","Al día")))))))) -> CONGELAR HOY | M24: Sí | N24: No aplica | O24: No aplica | P24: Incompleto | Q24: No enviada | U24: =IF(N($R24)=0,"",$T24/$R24) | V24: Levantamiento de información y materiales, falta brief formal | W24: 46218 | X24: =IF($W24="","",TODAY()-$W24) -> 19 | Y24: Cliente: Karol Añez. Dev histórico: Rubit. | Z24: =IFERROR(INDEX(Aarón!$P:$P,MATCH($C24,Aarón!$A:$A,0))&"",IFERROR(INDEX(Rubit!$P:$P,MATCH($C24,Rubit!$A:$A,0))&"",IFERROR(INDEX(Luis!$P:$P,MATCH($C24,Luis!$A:$A,0))&"",""))) | AA24: =IFERROR(INDEX(Aarón!$Q:$Q,MATCH($C24,Aarón!$A:$A,0))&"",IFERROR(INDEX(Rubit!$Q:$Q,MATCH($C24,Rubit!$A:$A,0))&"",IFERROR(INDEX(Luis!$Q:$Q,MATCH($C24,Luis!$A:$A,0))&"",""))) | AB24: =IFERROR(INDEX('Juan Carlos'!$Q:$Q,MATCH($C24,'Juan Carlos'!$A:$A,0))&"","")
A25: 2 | B25: 066 | C25: Erika Garay | E25: E-commerce | F25: Por definir | G25: Diseño | H25: Aarón | I25: Juan Carlos | J25: =IFERROR(INDEX('Juan Carlos'!$P:$P,MATCH($C25,'Juan Carlos'!$A:$A,0))&"","") -> Diseño en curso | K25: =IF($C25="","",IF($M25<>"Sí","C",IF($P25="Completo","A","B"))) -> A | L25: =IF($C25="","",IF($G25="Congelado","Congelado — mensaje cada 15 días",IF(N($X25)>15,"CONGELAR HOY",IF($M25<>"Sí","COBRAR EL 50%",IF($P25<>"Completo","PERSEGUIR MATERIAL",IF(AND($G25="Desarrollo",$N25<>"Sí"),"COBRAR EL 30%",IF(AND($G25="QA + entrega",$O25<>"Sí"),"COBRAR EL 20%",IF($G25="Cola","Listo para asignar","Al día")))))))) -> CONGELAR HOY | M25: Sí | N25: No aplica | O25: No aplica | P25: Completo | Q25: No enviada | U25: =IF(N($R25)=0,"",$T25/$R25) | V25: Material de diseño en general | W25: 46218 | X25: =IF($W25="","",TODAY()-$W25) -> 19 | Y25: Cliente: Erika Garay. Dev histórico: Aarón. | Z25: =IFERROR(INDEX(Aarón!$P:$P,MATCH($C25,Aarón!$A:$A,0))&"",IFERROR(INDEX(Rubit!$P:$P,MATCH($C25,Rubit!$A:$A,0))&"",IFERROR(INDEX(Luis!$P:$P,MATCH($C25,Luis!$A:$A,0))&"",""))) | AA25: =IFERROR(INDEX(Aarón!$Q:$Q,MATCH($C25,Aarón!$A:$A,0))&"",IFERROR(INDEX(Rubit!$Q:$Q,MATCH($C25,Rubit!$A:$A,0))&"",IFERROR(INDEX(Luis!$Q:$Q,MATCH($C25,Luis!$A:$A,0))&"",""))) | AB25: =IFERROR(INDEX('Juan Carlos'!$Q:$Q,MATCH($C25,'Juan Carlos'!$A:$A,0))&"","") -> en diseño
B26: 067 | C26: Ric Bian Originals | E26: E-commerce | F26: Por definir | G26: Diseño | H26: Rubit | I26: Juan Carlos | J26: =IFERROR(INDEX('Juan Carlos'!$P:$P,MATCH($C26,'Juan Carlos'!$A:$A,0))&"","") | K26: =IF($C26="","",IF($M26<>"Sí","C",IF($P26="Completo","A","B"))) -> B | L26: =IF($C26="","",IF($G26="Congelado","Congelado — mensaje cada 15 días",IF(N($X26)>15,"CONGELAR HOY",IF($M26<>"Sí","COBRAR EL 50%",IF($P26<>"Completo","PERSEGUIR MATERIAL",IF(AND($G26="Desarrollo",$N26<>"Sí"),"COBRAR EL 30%",IF(AND($G26="QA + entrega",$O26<>"Sí"),"COBRAR EL 20%",IF($G26="Cola","Listo para asignar","Al día")))))))) -> CONGELAR HOY | M26: Sí | N26: No aplica | O26: No aplica | P26: Incompleto | Q26: No enviada | U26: =IF(N($R26)=0,"",$T26/$R26) | V26: Material de diseño en general | W26: 46218 | X26: =IF($W26="","",TODAY()-$W26) -> 19 | Y26: Cliente: Romel. Dev histórico: Rubit.- espera de manual de marca websy , si pudieron algunas de las propuestas de logotipo | Z26: =IFERROR(INDEX(Aarón!$P:$P,MATCH($C26,Aarón!$A:$A,0))&"",IFERROR(INDEX(Rubit!$P:$P,MATCH($C26,Rubit!$A:$A,0))&"",IFERROR(INDEX(Luis!$P:$P,MATCH($C26,Luis!$A:$A,0))&"",""))) | AA26: =IFERROR(INDEX(Aarón!$Q:$Q,MATCH($C26,Aarón!$A:$A,0))&"",IFERROR(INDEX(Rubit!$Q:$Q,MATCH($C26,Rubit!$A:$A,0))&"",IFERROR(INDEX(Luis!$Q:$Q,MATCH($C26,Luis!$A:$A,0))&"",""))) | AB26: =IFERROR(INDEX('Juan Carlos'!$Q:$Q,MATCH($C26,'Juan Carlos'!$A:$A,0))&"","")
A27: 11 | B27: 068 | C27: Camaleon | E27: E-commerce | F27: Por definir | G27: Esperando material | H27: Aarón | I27: Juan Carlos | J27: =IFERROR(INDEX('Juan Carlos'!$P:$P,MATCH($C27,'Juan Carlos'!$A:$A,0))&"","") | K27: =IF($C27="","",IF($M27<>"Sí","C",IF($P27="Completo","A","B"))) -> B | L27: =IF($C27="","",IF($G27="Congelado","Congelado — mensaje cada 15 días",IF(N($X27)>15,"CONGELAR HOY",IF($M27<>"Sí","COBRAR EL 50%",IF($P27<>"Completo","PERSEGUIR MATERIAL",IF(AND($G27="Desarrollo",$N27<>"Sí"),"COBRAR EL 30%",IF(AND($G27="QA + entrega",$O27<>"Sí"),"COBRAR EL 20%",IF($G27="Cola","Listo para asignar","Al día")))))))) -> CONGELAR HOY | M27: Sí | N27: No aplica | O27: No aplica | P27: Nada | Q27: No enviada | U27: =IF(N($R27)=0,"",$T27/$R27) | V27: Todo — recién se llenó el brief | W27: 46219 | X27: =IF($W27="","",TODAY()-$W27) -> 18 | Y27: Cliente: Lady Quispe. Dev histórico: Aarón. Marca previa de Juan Carlos (el proyecto salió de su hoja por no estar en grupo A): «PERSEGUIR». | Z27: =IFERROR(INDEX(Aarón!$P:$P,MATCH($C27,Aarón!$A:$A,0))&"",IFERROR(INDEX(Rubit!$P:$P,MATCH($C27,Rubit!$A:$A,0))&"",IFERROR(INDEX(Luis!$P:$P,MATCH($C27,Luis!$A:$A,0))&"",""))) | AA27: =IFERROR(INDEX(Aarón!$Q:$Q,MATCH($C27,Aarón!$A:$A,0))&"",IFERROR(INDEX(Rubit!$Q:$Q,MATCH($C27,Rubit!$A:$A,0))&"",IFERROR(INDEX(Luis!$Q:$Q,MATCH($C27,Luis!$A:$A,0))&"",""))) | AB27: =IFERROR(INDEX('Juan Carlos'!$Q:$Q,MATCH($C27,'Juan Carlos'!$A:$A,0))&"","")
A28: 6 | B28: 069 | C28: Global Peru Renting | E28: Informativa | F28: Por definir | G28: Diseño | H28: Rubit | I28: Juan Carlos | J28: =IFERROR(INDEX('Juan Carlos'!$P:$P,MATCH($C28,'Juan Carlos'!$A:$A,0))&"","") | K28: =IF($C28="","",IF($M28<>"Sí","C",IF($P28="Completo","A","B"))) -> B | L28: =IF($C28="","",IF($G28="Congelado","Congelado — mensaje cada 15 días",IF(N($X28)>15,"CONGELAR HOY",IF($M28<>"Sí","COBRAR EL 50%",IF($P28<>"Completo","PERSEGUIR MATERIAL",IF(AND($G28="Desarrollo",$N28<>"Sí"),"COBRAR EL 30%",IF(AND($G28="QA + entrega",$O28<>"Sí"),"COBRAR EL 20%",IF($G28="Cola","Listo para asignar","Al día")))))))) -> CONGELAR HOY | M28: Sí | N28: No aplica | O28: No aplica | P28: Incompleto | Q28: No aplica | U28: =IF(N($R28)=0,"",$T28/$R28) | V28: Nada — en proceso de diseño | W28: 46218 | X28: =IF($W28="","",TODAY()-$W28) -> 19 | Y28: Cliente: Erika Ventura. Dev histórico: Rubit. , que suban sus archivos al drive Marca previa de Juan Carlos (el proyecto salió de su hoja por no estar en grupo A): «avance listo». | Z28: =IFERROR(INDEX(Aarón!$P:$P,MATCH($C28,Aarón!$A:$A,0))&"",IFERROR(INDEX(Rubit!$P:$P,MATCH($C28,Rubit!$A:$A,0))&"",IFERROR(INDEX(Luis!$P:$P,MATCH($C28,Luis!$A:$A,0))&"",""))) | AA28: =IFERROR(INDEX(Aarón!$Q:$Q,MATCH($C28,Aarón!$A:$A,0))&"",IFERROR(INDEX(Rubit!$Q:$Q,MATCH($C28,Rubit!$A:$A,0))&"",IFERROR(INDEX(Luis!$Q:$Q,MATCH($C28,Luis!$A:$A,0))&"",""))) | AB28: =IFERROR(INDEX('Juan Carlos'!$Q:$Q,MATCH($C28,'Juan Carlos'!$A:$A,0))&"","")
A29: 7 | B29: 070 | C29: Buzz Studios | E29: E-commerce | F29: Por definir | G29: Diseño | H29: Aarón | I29: Juan Carlos | J29: =IFERROR(INDEX('Juan Carlos'!$P:$P,MATCH($C29,'Juan Carlos'!$A:$A,0))&"","") -> Diseño en curso | K29: =IF($C29="","",IF($M29<>"Sí","C",IF($P29="Completo","A","B"))) -> A | L29: =IF($C29="","",IF($G29="Congelado","Congelado — mensaje cada 15 días",IF(N($X29)>15,"CONGELAR HOY",IF($M29<>"Sí","COBRAR EL 50%",IF($P29<>"Completo","PERSEGUIR MATERIAL",IF(AND($G29="Desarrollo",$N29<>"Sí"),"COBRAR EL 30%",IF(AND($G29="QA + entrega",$O29<>"Sí"),"COBRAR EL 20%",IF($G29="Cola","Listo para asignar","Al día")))))))) -> CONGELAR HOY | M29: Sí | N29: No aplica | O29: No aplica | P29: Completo | Q29: No enviada | U29: =IF(N($R29)=0,"",$T29/$R29) | V29: Material de diseño (brief y drive ya completados administrativamente) | W29: 46218 | X29: =IF($W29="","",TODAY()-$W29) -> 19 | Y29: Cliente: Elvis Stefano. Dev histórico: Aarón. | Z29: =IFERROR(INDEX(Aarón!$P:$P,MATCH($C29,Aarón!$A:$A,0))&"",IFERROR(INDEX(Rubit!$P:$P,MATCH($C29,Rubit!$A:$A,0))&"",IFERROR(INDEX(Luis!$P:$P,MATCH($C29,Luis!$A:$A,0))&"",""))) | AA29: =IFERROR(INDEX(Aarón!$Q:$Q,MATCH($C29,Aarón!$A:$A,0))&"",IFERROR(INDEX(Rubit!$Q:$Q,MATCH($C29,Rubit!$A:$A,0))&"",IFERROR(INDEX(Luis!$Q:$Q,MATCH($C29,Luis!$A:$A,0))&"",""))) | AB29: =IFERROR(INDEX('Juan Carlos'!$Q:$Q,MATCH($C29,'Juan Carlos'!$A:$A,0))&"","") -> Lunes
A30: 5 | B30: 071 | C30: Teccons SAC | E30: Informativa | F30: Por definir | G30: Diseño | H30: Rubit | I30: Juan Carlos | J30: =IFERROR(INDEX('Juan Carlos'!$P:$P,MATCH($C30,'Juan Carlos'!$A:$A,0))&"","") -> Avance listo para presentar | K30: =IF($C30="","",IF($M30<>"Sí","C",IF($P30="Completo","A","B"))) -> A | L30: =IF($C30="","",IF($G30="Congelado","Congelado — mensaje cada 15 días",IF(N($X30)>15,"CONGELAR HOY",IF($M30<>"Sí","COBRAR EL 50%",IF($P30<>"Completo","PERSEGUIR MATERIAL",IF(AND($G30="Desarrollo",$N30<>"Sí"),"COBRAR EL 30%",IF(AND($G30="QA + entrega",$O30<>"Sí"),"COBRAR EL 20%",IF($G30="Cola","Listo para asignar","Al día")))))))) -> CONGELAR HOY | M30: Sí | N30: No aplica | O30: No aplica | P30: Completo | Q30: No aplica | U30: =IF(N($R30)=0,"",$T30/$R30) | V30: Material de diseño (brief y drive ya completados administrativamente) | W30: 46218 | X30: =IF($W30="","",TODAY()-$W30) -> 19 | Y30: Cliente: Jhon Cabrera Sánchez. Dev histórico: Rubit. | Z30: =IFERROR(INDEX(Aarón!$P:$P,MATCH($C30,Aarón!$A:$A,0))&"",IFERROR(INDEX(Rubit!$P:$P,MATCH($C30,Rubit!$A:$A,0))&"",IFERROR(INDEX(Luis!$P:$P,MATCH($C30,Luis!$A:$A,0))&"",""))) | AA30: =IFERROR(INDEX(Aarón!$Q:$Q,MATCH($C30,Aarón!$A:$A,0))&"",IFERROR(INDEX(Rubit!$Q:$Q,MATCH($C30,Rubit!$A:$A,0))&"",IFERROR(INDEX(Luis!$Q:$Q,MATCH($C30,Luis!$A:$A,0))&"",""))) | AB30: =IFERROR(INDEX('Juan Carlos'!$Q:$Q,MATCH($C30,'Juan Carlos'!$A:$A,0))&"","") -> avance listo
A31: 8 | B31: 073 | C31: Hasso Group | E31: E-commerce | F31: Por definir | G31: Diseño | H31: Rubit | I31: Juan Carlos | J31: =IFERROR(INDEX('Juan Carlos'!$P:$P,MATCH($C31,'Juan Carlos'!$A:$A,0))&"","") -> Material completo — iniciar diseño | K31: =IF($C31="","",IF($M31<>"Sí","C",IF($P31="Completo","A","B"))) -> A | L31: =IF($C31="","",IF($G31="Congelado","Congelado — mensaje cada 15 días",IF(N($X31)>15,"CONGELAR HOY",IF($M31<>"Sí","COBRAR EL 50%",IF($P31<>"Completo","PERSEGUIR MATERIAL",IF(AND($G31="Desarrollo",$N31<>"Sí"),"COBRAR EL 30%",IF(AND($G31="QA + entrega",$O31<>"Sí"),"COBRAR EL 20%",IF($G31="Cola","Listo para asignar","Al día")))))))) -> CONGELAR HOY | M31: Sí | N31: No aplica | O31: No aplica | P31: Completo | Q31: No enviada | U31: =IF(N($R31)=0,"",$T31/$R31) | V31: Materiales y activos del cliente para iniciar estructura de la tienda | W31: 46218 | X31: =IF($W31="","",TODAY()-$W31) -> 19 | Y31: Cliente: Sharmely Zanabria Carmona. Dev histórico: Rubit. Enviar materiales logotipos y fotos | Z31: =IFERROR(INDEX(Aarón!$P:$P,MATCH($C31,Aarón!$A:$A,0))&"",IFERROR(INDEX(Rubit!$P:$P,MATCH($C31,Rubit!$A:$A,0))&"",IFERROR(INDEX(Luis!$P:$P,MATCH($C31,Luis!$A:$A,0))&"",""))) | AA31: =IFERROR(INDEX(Aarón!$Q:$Q,MATCH($C31,Aarón!$A:$A,0))&"",IFERROR(INDEX(Rubit!$Q:$Q,MATCH($C31,Rubit!$A:$A,0))&"",IFERROR(INDEX(Luis!$Q:$Q,MATCH($C31,Luis!$A:$A,0))&"",""))) | AB31: =IFERROR(INDEX('Juan Carlos'!$Q:$Q,MATCH($C31,'Juan Carlos'!$A:$A,0))&"","")
A32: 3 | B32: 074 | C32: HSM Foods & Agro | E32: E-commerce | F32: Por definir | G32: Diseño | H32: Aarón | I32: Juan Carlos | J32: =IFERROR(INDEX('Juan Carlos'!$P:$P,MATCH($C32,'Juan Carlos'!$A:$A,0))&"","") -> Material completo — iniciar diseño | K32: =IF($C32="","",IF($M32<>"Sí","C",IF($P32="Completo","A","B"))) -> A | L32: =IF($C32="","",IF($G32="Congelado","Congelado — mensaje cada 15 días",IF(N($X32)>15,"CONGELAR HOY",IF($M32<>"Sí","COBRAR EL 50%",IF($P32<>"Completo","PERSEGUIR MATERIAL",IF(AND($G32="Desarrollo",$N32<>"Sí"),"COBRAR EL 30%",IF(AND($G32="QA + entrega",$O32<>"Sí"),"COBRAR EL 20%",IF($G32="Cola","Listo para asignar","Al día")))))))) -> CONGELAR HOY | M32: Sí | N32: No aplica | O32: No aplica | P32: Completo | Q32: Recibida con errores | R32: 110 | U32: =IF(N($R32)=0,"",$T32/$R32) -> 0 | V32: Fotos (comprometidas para la próxima semana) | W32: 46218 | X32: =IF($W32="","",TODAY()-$W32) -> 19 | Y32: Cliente: Sebastian y Mauricio. Dev histórico: Aarón. PENDIENTE: subir las fotos al Drive. Pedir en el grupo que suban el brief al Drive para que Luis lo descargue. | Z32: =IFERROR(INDEX(Aarón!$P:$P,MATCH($C32,Aarón!$A:$A,0))&"",IFERROR(INDEX(Rubit!$P:$P,MATCH($C32,Rubit!$A:$A,0))&"",IFERROR(INDEX(Luis!$P:$P,MATCH($C32,Luis!$A:$A,0))&"",""))) | AA32: =IFERROR(INDEX(Aarón!$Q:$Q,MATCH($C32,Aarón!$A:$A,0))&"",IFERROR(INDEX(Rubit!$Q:$Q,MATCH($C32,Rubit!$A:$A,0))&"",IFERROR(INDEX(Luis!$Q:$Q,MATCH($C32,Luis!$A:$A,0))&"",""))) | AB32: =IFERROR(INDEX('Juan Carlos'!$Q:$Q,MATCH($C32,'Juan Carlos'!$A:$A,0))&"","")
A33: 4 | B33: 075 | C33: Luma Home | E33: E-commerce | F33: Por definir | G33: Diseño | H33: Rubit | I33: Juan Carlos | J33: =IFERROR(INDEX('Juan Carlos'!$P:$P,MATCH($C33,'Juan Carlos'!$A:$A,0))&"","") -> Material completo — iniciar diseño | K33: =IF($C33="","",IF($M33<>"Sí","C",IF($P33="Completo","A","B"))) -> A | L33: =IF($C33="","",IF($G33="Congelado","Congelado — mensaje cada 15 días",IF(N($X33)>15,"CONGELAR HOY",IF($M33<>"Sí","COBRAR EL 50%",IF($P33<>"Completo","PERSEGUIR MATERIAL",IF(AND($G33="Desarrollo",$N33<>"Sí"),"COBRAR EL 30%",IF(AND($G33="QA + entrega",$O33<>"Sí"),"COBRAR EL 20%",IF($G33="Cola","Listo para asignar","Al día")))))))) -> CONGELAR HOY | M33: Sí | N33: No aplica | O33: No aplica | P33: Completo | Q33: No enviada | U33: =IF(N($R33)=0,"",$T33/$R33) | V33: Material de diseño (brief y drive ya completados administrativamente) | W33: 46218 | X33: =IF($W33="","",TODAY()-$W33) -> 19 | Y33: Cliente: Fatima. Dev histórico: Rubit. PENDIENTE: que envíen todo su material al Drive. | Z33: =IFERROR(INDEX(Aarón!$P:$P,MATCH($C33,Aarón!$A:$A,0))&"",IFERROR(INDEX(Rubit!$P:$P,MATCH($C33,Rubit!$A:$A,0))&"",IFERROR(INDEX(Luis!$P:$P,MATCH($C33,Luis!$A:$A,0))&"",""))) | AA33: =IFERROR(INDEX(Aarón!$Q:$Q,MATCH($C33,Aarón!$A:$A,0))&"",IFERROR(INDEX(Rubit!$Q:$Q,MATCH($C33,Rubit!$A:$A,0))&"",IFERROR(INDEX(Luis!$Q:$Q,MATCH($C33,Luis!$A:$A,0))&"",""))) | AB33: =IFERROR(INDEX('Juan Carlos'!$Q:$Q,MATCH($C33,'Juan Carlos'!$A:$A,0))&"","")
A34: 10 | B34: 076 | C34: Raul Cabana | E34: E-commerce | F34: Por definir | G34: Cola | H34: Aarón | I34: Juan Carlos | J34: =IFERROR(INDEX('Juan Carlos'!$P:$P,MATCH($C34,'Juan Carlos'!$A:$A,0))&"","") | K34: =IF($C34="","",IF($M34<>"Sí","C",IF($P34="Completo","A","B"))) -> B | L34: =IF($C34="","",IF($G34="Congelado","Congelado — mensaje cada 15 días",IF(N($X34)>15,"CONGELAR HOY",IF($M34<>"Sí","COBRAR EL 50%",IF($P34<>"Completo","PERSEGUIR MATERIAL",IF(AND($G34="Desarrollo",$N34<>"Sí"),"COBRAR EL 30%",IF(AND($G34="QA + entrega",$O34<>"Sí"),"COBRAR EL 20%",IF($G34="Cola","Listo para asignar","Al día")))))))) -> CONGELAR HOY | M34: Sí | N34: No aplica | O34: No aplica | P34: Incompleto | Q34: No enviada | U34: =IF(N($R34)=0,"",$T34/$R34) | V34: Material de diseño en general | W34: 46218 | X34: =IF($W34="","",TODAY()-$W34) -> 19 | Y34: Cliente: Raul Cabana. Dev histórico: Aarón. | Z34: =IFERROR(INDEX(Aarón!$P:$P,MATCH($C34,Aarón!$A:$A,0))&"",IFERROR(INDEX(Rubit!$P:$P,MATCH($C34,Rubit!$A:$A,0))&"",IFERROR(INDEX(Luis!$P:$P,MATCH($C34,Luis!$A:$A,0))&"",""))) | AA34: =IFERROR(INDEX(Aarón!$Q:$Q,MATCH($C34,Aarón!$A:$A,0))&"",IFERROR(INDEX(Rubit!$Q:$Q,MATCH($C34,Rubit!$A:$A,0))&"",IFERROR(INDEX(Luis!$Q:$Q,MATCH($C34,Luis!$A:$A,0))&"",""))) | AB34: =IFERROR(INDEX('Juan Carlos'!$Q:$Q,MATCH($C34,'Juan Carlos'!$A:$A,0))&"","")
B35: 077 | C35: Editora Desarrollo Humano | E35: Informativa | F35: Por definir | G35: Desarrollo | H35: Luis | I35: Juan Carlos | J35: =IFERROR(INDEX('Juan Carlos'!$P:$P,MATCH($C35,'Juan Carlos'!$A:$A,0))&"","") | K35: =IF($C35="","",IF($M35<>"Sí","C",IF($P35="Completo","A","B"))) -> C | L35: =IF($C35="","",IF($G35="Congelado","Congelado — mensaje cada 15 días",IF(N($X35)>15,"CONGELAR HOY",IF($M35<>"Sí","COBRAR EL 50%",IF($P35<>"Completo","PERSEGUIR MATERIAL",IF(AND($G35="Desarrollo",$N35<>"Sí"),"COBRAR EL 30%",IF(AND($G35="QA + entrega",$O35<>"Sí"),"COBRAR EL 20%",IF($G35="Cola","Listo para asignar","Al día")))))))) -> CONGELAR HOY | M35: No aplica | N35: No aplica | O35: No aplica | P35: Incompleto | Q35: No aplica | U35: =IF(N($R35)=0,"",$T35/$R35) | V35: Material de diseño / contenidos (proyecto de branding + intranet + LMS) | W35: 46218 | X35: =IF($W35="","",TODAY()-$W35) -> 19 | Y35: Cliente: Maria Gracia. Luis mencionado como responsable — capacidad 0 según Reglas, confirmar quién lo lleva en la práctica. | Z35: =IFERROR(INDEX(Aarón!$P:$P,MATCH($C35,Aarón!$A:$A,0))&"",IFERROR(INDEX(Rubit!$P:$P,MATCH($C35,Rubit!$A:$A,0))&"",IFERROR(INDEX(Luis!$P:$P,MATCH($C35,Luis!$A:$A,0))&"",""))) | AA35: =IFERROR(INDEX(Aarón!$Q:$Q,MATCH($C35,Aarón!$A:$A,0))&"",IFERROR(INDEX(Rubit!$Q:$Q,MATCH($C35,Rubit!$A:$A,0))&"",IFERROR(INDEX(Luis!$Q:$Q,MATCH($C35,Luis!$A:$A,0))&"",""))) | AB35: =IFERROR(INDEX('Juan Carlos'!$Q:$Q,MATCH($C35,'Juan Carlos'!$A:$A,0))&"","")
B36: 078 | C36: Guardiania Total 360 | E36: Informativa | F36: Por definir | G36: Esperando material | H36: Rubit | I36: Juan Carlos | J36: =IFERROR(INDEX('Juan Carlos'!$P:$P,MATCH($C36,'Juan Carlos'!$A:$A,0))&"","") | K36: =IF($C36="","",IF($M36<>"Sí","C",IF($P36="Completo","A","B"))) -> B | L36: =IF($C36="","",IF($G36="Congelado","Congelado — mensaje cada 15 días",IF(N($X36)>15,"CONGELAR HOY",IF($M36<>"Sí","COBRAR EL 50%",IF($P36<>"Completo","PERSEGUIR MATERIAL",IF(AND($G36="Desarrollo",$N36<>"Sí"),"COBRAR EL 30%",IF(AND($G36="QA + entrega",$O36<>"Sí"),"COBRAR EL 20%",IF($G36="Cola","Listo para asignar","Al día")))))))) -> CONGELAR HOY | M36: Sí | N36: No aplica | O36: No aplica | P36: Incompleto | Q36: No aplica | U36: =IF(N($R36)=0,"",$T36/$R36) | V36: Material de diseño en general | W36: 46218 | X36: =IF($W36="","",TODAY()-$W36) -> 19 | Y36: Cliente: Kenny. Dev histórico: Rubit. | Z36: =IFERROR(INDEX(Aarón!$P:$P,MATCH($C36,Aarón!$A:$A,0))&"",IFERROR(INDEX(Rubit!$P:$P,MATCH($C36,Rubit!$A:$A,0))&"",IFERROR(INDEX(Luis!$P:$P,MATCH($C36,Luis!$A:$A,0))&"",""))) | AA36: =IFERROR(INDEX(Aarón!$Q:$Q,MATCH($C36,Aarón!$A:$A,0))&"",IFERROR(INDEX(Rubit!$Q:$Q,MATCH($C36,Rubit!$A:$A,0))&"",IFERROR(INDEX(Luis!$Q:$Q,MATCH($C36,Luis!$A:$A,0))&"",""))) | AB36: =IFERROR(INDEX('Juan Carlos'!$Q:$Q,MATCH($C36,'Juan Carlos'!$A:$A,0))&"","")
B37: 079 | C37: Doctor G | E37: Informativa | F37: Por definir | G37: Cola | H37: Aarón | I37: Juan Carlos | J37: =IFERROR(INDEX('Juan Carlos'!$P:$P,MATCH($C37,'Juan Carlos'!$A:$A,0))&"","") | K37: =IF($C37="","",IF($M37<>"Sí","C",IF($P37="Completo","A","B"))) -> A | L37: =IF($C37="","",IF($G37="Congelado","Congelado — mensaje cada 15 días",IF(N($X37)>15,"CONGELAR HOY",IF($M37<>"Sí","COBRAR EL 50%",IF($P37<>"Completo","PERSEGUIR MATERIAL",IF(AND($G37="Desarrollo",$N37<>"Sí"),"COBRAR EL 30%",IF(AND($G37="QA + entrega",$O37<>"Sí"),"COBRAR EL 20%",IF($G37="Cola","Listo para asignar","Al día")))))))) -> Listo para asignar | M37: Sí | N37: No aplica | O37: No aplica | P37: Completo | Q37: No aplica | U37: =IF(N($R37)=0,"",$T37/$R37) | V37: Todo — sin información registrada aún | X37: =IF($W37="","",TODAY()-$W37) | Y37: Dev histórico: Aarón. Cliente sin identificar en los registros — confirmar nombre. Viernes 24/07 cinco pm | Z37: =IFERROR(INDEX(Aarón!$P:$P,MATCH($C37,Aarón!$A:$A,0))&"",IFERROR(INDEX(Rubit!$P:$P,MATCH($C37,Rubit!$A:$A,0))&"",IFERROR(INDEX(Luis!$P:$P,MATCH($C37,Luis!$A:$A,0))&"",""))) | AA37: =IFERROR(INDEX(Aarón!$Q:$Q,MATCH($C37,Aarón!$A:$A,0))&"",IFERROR(INDEX(Rubit!$Q:$Q,MATCH($C37,Rubit!$A:$A,0))&"",IFERROR(INDEX(Luis!$Q:$Q,MATCH($C37,Luis!$A:$A,0))&"",""))) | AB37: =IFERROR(INDEX('Juan Carlos'!$Q:$Q,MATCH($C37,'Juan Carlos'!$A:$A,0))&"","")
C38: Alpen Ingenieros | E38: Informativa | F38: Por definir | G38: Cerrado | H38: Luis | I38: Juan Carlos | J38: =IFERROR(INDEX('Juan Carlos'!$P:$P,MATCH($C38,'Juan Carlos'!$A:$A,0))&"","") | K38: =IF($C38="","",IF($M38<>"Sí","C",IF($P38="Completo","A","B"))) -> A | L38: =IF($C38="","",IF($G38="Congelado","Congelado — mensaje cada 15 días",IF(N($X38)>15,"CONGELAR HOY",IF($M38<>"Sí","COBRAR EL 50%",IF($P38<>"Completo","PERSEGUIR MATERIAL",IF(AND($G38="Desarrollo",$N38<>"Sí"),"COBRAR EL 30%",IF(AND($G38="QA + entrega",$O38<>"Sí"),"COBRAR EL 20%",IF($G38="Cola","Listo para asignar","Al día")))))))) -> Al día | M38: Sí | N38: Sí | O38: Sí | P38: Completo | Q38: No aplica | U38: =IF(N($R38)=0,"",$T38/$R38) | V38: Todo — lead sin pago ni código | X38: =IF($W38="","",TODAY()-$W38) | Y38: Cliente: Leonardo. | Z38: =IFERROR(INDEX(Aarón!$P:$P,MATCH($C38,Aarón!$A:$A,0))&"",IFERROR(INDEX(Rubit!$P:$P,MATCH($C38,Rubit!$A:$A,0))&"",IFERROR(INDEX(Luis!$P:$P,MATCH($C38,Luis!$A:$A,0))&"",""))) | AA38: =IFERROR(INDEX(Aarón!$Q:$Q,MATCH($C38,Aarón!$A:$A,0))&"",IFERROR(INDEX(Rubit!$Q:$Q,MATCH($C38,Rubit!$A:$A,0))&"",IFERROR(INDEX(Luis!$Q:$Q,MATCH($C38,Luis!$A:$A,0))&"",""))) | AB38: =IFERROR(INDEX('Juan Carlos'!$Q:$Q,MATCH($C38,'Juan Carlos'!$A:$A,0))&"","")
C39: Evi | E39: E-commerce | F39: Por definir | G39: Cerrado | H39: Luis | I39: Juan Carlos | J39: =IFERROR(INDEX('Juan Carlos'!$P:$P,MATCH($C39,'Juan Carlos'!$A:$A,0))&"","") | K39: =IF($C39="","",IF($M39<>"Sí","C",IF($P39="Completo","A","B"))) -> A | L39: =IF($C39="","",IF($G39="Congelado","Congelado — mensaje cada 15 días",IF(N($X39)>15,"CONGELAR HOY",IF($M39<>"Sí","COBRAR EL 50%",IF($P39<>"Completo","PERSEGUIR MATERIAL",IF(AND($G39="Desarrollo",$N39<>"Sí"),"COBRAR EL 30%",IF(AND($G39="QA + entrega",$O39<>"Sí"),"COBRAR EL 20%",IF($G39="Cola","Listo para asignar","Al día")))))))) -> Al día | M39: Sí | N39: Sí | O39: Sí | P39: Completo | Q39: Recibida y validada | U39: =IF(N($R39)=0,"",$T39/$R39) | V39: Todo — lead sin pago ni código | X39: =IF($W39="","",TODAY()-$W39) | Y39: Cliente: Evi. | Z39: =IFERROR(INDEX(Aarón!$P:$P,MATCH($C39,Aarón!$A:$A,0))&"",IFERROR(INDEX(Rubit!$P:$P,MATCH($C39,Rubit!$A:$A,0))&"",IFERROR(INDEX(Luis!$P:$P,MATCH($C39,Luis!$A:$A,0))&"",""))) | AA39: =IFERROR(INDEX(Aarón!$Q:$Q,MATCH($C39,Aarón!$A:$A,0))&"",IFERROR(INDEX(Rubit!$Q:$Q,MATCH($C39,Rubit!$A:$A,0))&"",IFERROR(INDEX(Luis!$Q:$Q,MATCH($C39,Luis!$A:$A,0))&"",""))) | AB39: =IFERROR(INDEX('Juan Carlos'!$Q:$Q,MATCH($C39,'Juan Carlos'!$A:$A,0))&"","")
C40: WJ Repuestos | E40: E-commerce | F40: Por definir | G40: Cerrado | H40: Aarón | I40: Juan Carlos | J40: =IFERROR(INDEX('Juan Carlos'!$P:$P,MATCH($C40,'Juan Carlos'!$A:$A,0))&"","") | K40: =IF($C40="","",IF($M40<>"Sí","C",IF($P40="Completo","A","B"))) -> A | L40: =IF($C40="","",IF($G40="Congelado","Congelado — mensaje cada 15 días",IF(N($X40)>15,"CONGELAR HOY",IF($M40<>"Sí","COBRAR EL 50%",IF($P40<>"Completo","PERSEGUIR MATERIAL",IF(AND($G40="Desarrollo",$N40<>"Sí"),"COBRAR EL 30%",IF(AND($G40="QA + entrega",$O40<>"Sí"),"COBRAR EL 20%",IF($G40="Cola","Listo para asignar","Al día")))))))) -> Al día | M40: Sí | N40: Sí | O40: Sí | P40: Completo | Q40: Recibida y validada | U40: =IF(N($R40)=0,"",$T40/$R40) | V40: Todo — lead sin pago ni código | X40: =IF($W40="","",TODAY()-$W40) | Y40: Cliente: Mariajose y Jon. | Z40: =IFERROR(INDEX(Aarón!$P:$P,MATCH($C40,Aarón!$A:$A,0))&"",IFERROR(INDEX(Rubit!$P:$P,MATCH($C40,Rubit!$A:$A,0))&"",IFERROR(INDEX(Luis!$P:$P,MATCH($C40,Luis!$A:$A,0))&"",""))) | AA40: =IFERROR(INDEX(Aarón!$Q:$Q,MATCH($C40,Aarón!$A:$A,0))&"",IFERROR(INDEX(Rubit!$Q:$Q,MATCH($C40,Rubit!$A:$A,0))&"",IFERROR(INDEX(Luis!$Q:$Q,MATCH($C40,Luis!$A:$A,0))&"",""))) | AB40: =IFERROR(INDEX('Juan Carlos'!$Q:$Q,MATCH($C40,'Juan Carlos'!$A:$A,0))&"","")
C41: Bellucci | E41: E-commerce | F41: Por definir | G41: Cerrado | H41: Aarón | I41: Juan Carlos | J41: =IFERROR(INDEX('Juan Carlos'!$P:$P,MATCH($C41,'Juan Carlos'!$A:$A,0))&"","") -> Diseño finalizado | K41: =IF($C41="","",IF($M41<>"Sí","C",IF($P41="Completo","A","B"))) -> A | L41: =IF($C41="","",IF($G41="Congelado","Congelado — mensaje cada 15 días",IF(N($X41)>15,"CONGELAR HOY",IF($M41<>"Sí","COBRAR EL 50%",IF($P41<>"Completo","PERSEGUIR MATERIAL",IF(AND($G41="Desarrollo",$N41<>"Sí"),"COBRAR EL 30%",IF(AND($G41="QA + entrega",$O41<>"Sí"),"COBRAR EL 20%",IF($G41="Cola","Listo para asignar","Al día")))))))) -> Al día | M41: Sí | N41: Sí | O41: Sí | P41: Completo | Q41: Recibida y validada | S41: faltante | U41: =IF(N($R41)=0,"",$T41/$R41) | V41: Todo — lead sin pago ni código | X41: =IF($W41="","",TODAY()-$W41) | Y41: Cliente: Joselyn Mendoza Vasquez. | Z41: =IFERROR(INDEX(Aarón!$P:$P,MATCH($C41,Aarón!$A:$A,0))&"",IFERROR(INDEX(Rubit!$P:$P,MATCH($C41,Rubit!$A:$A,0))&"",IFERROR(INDEX(Luis!$P:$P,MATCH($C41,Luis!$A:$A,0))&"",""))) | AA41: =IFERROR(INDEX(Aarón!$Q:$Q,MATCH($C41,Aarón!$A:$A,0))&"",IFERROR(INDEX(Rubit!$Q:$Q,MATCH($C41,Rubit!$A:$A,0))&"",IFERROR(INDEX(Luis!$Q:$Q,MATCH($C41,Luis!$A:$A,0))&"",""))) | AB41: =IFERROR(INDEX('Juan Carlos'!$Q:$Q,MATCH($C41,'Juan Carlos'!$A:$A,0))&"","")
...

Sheet Tablero
B2: Tablero del área
B3: Todo lo de esta hoja se dibuja solo con lo que escribes en PROYECTOS. No se edita nada aquí.
B5: =COUNTIF(Proyectos!$K$4:$K$60,"A") -> 31 | D5: =COUNTIF(Proyectos!$K$4:$K$60,"B") -> 16 | F5: =COUNTIF(Proyectos!$K$4:$K$60,"C") -> 1 | H5: =COUNTIF(Proyectos!$X$4:$X$60,">15") -> 30 | J5: =COUNTIF(Proyectos!$G$4:$G$60,"Cerrado") -> 18
B6: Listos para producir | D6: Trabados por el cliente | F6: Sin pagar / sin responder | H6: Para congelar hoy | J6: Cerrados
B9: En qué etapa está cada proyecto
B10: Cola | C10: =COUNTIF(Proyectos!$G$4:$G$60,"Cola") -> 2
B11: Esperando material | C11: =COUNTIF(Proyectos!$G$4:$G$60,"Esperando material") -> 6
B12: Diseño | C12: =COUNTIF(Proyectos!$G$4:$G$60,"Diseño") -> 11
B13: Desarrollo | C13: =COUNTIF(Proyectos!$G$4:$G$60,"Desarrollo") -> 6
B14: Esperando catálogo | C14: =COUNTIF(Proyectos!$G$4:$G$60,"Esperando catálogo") -> 0
B15: QA + entrega | C15: =COUNTIF(Proyectos!$G$4:$G$60,"QA + entrega") -> 1
B16: Cerrado | C16: =COUNTIF(Proyectos!$G$4:$G$60,"Cerrado") -> 18
B17: Congelado | C17: =COUNTIF(Proyectos!$G$4:$G$60,"Congelado") -> 4
B20: Cuánto trabajo tiene cada uno ahora | E20: En qué plataforma va cada tienda | H20: Avance de diseño (Juan Carlos)
B21: Juan Carlos (diseño, grupo A) | C21: =COUNTIFS(Proyectos!$K$4:$K$60,"A",Proyectos!$G$4:$G$60,"<>Cerrado",Proyectos!$G$4:$G$60,"<>Congelado",Proyectos!$C$4:$C$60,"<>") -> 13 | E21: Shopify | F21: =COUNTIF(Proyectos!$F$4:$F$60,"Shopify") -> 1 | H21: Falta material | I21: =COUNTIF(Proyectos!$J$4:$J$60,"Falta material") -> 0
B22: Aarón (desarrollo) | C22: =COUNTIFS(Proyectos!$H$4:$H$60,"Aarón",Proyectos!$G$4:$G$60,"Desarrollo") -> 3 | E22: WooCommerce | F22: =COUNTIF(Proyectos!$F$4:$F$60,"WooCommerce") -> 1 | H22: Material completo — iniciar diseño | I22: =COUNTIF(Proyectos!$J$4:$J$60,"Material completo — iniciar diseño") -> 4
B23: Rubit (desarrollo) | C23: =COUNTIFS(Proyectos!$H$4:$H$60,"Rubit",Proyectos!$G$4:$G$60,"Desarrollo") -> 0 | E23: Personalizado | F23: =COUNTIF(Proyectos!$F$4:$F$60,"Personalizado") -> 0 | H23: Diseño en curso | I23: =COUNTIF(Proyectos!$J$4:$J$60,"Diseño en curso") -> 2
B24: Luis (desarrollo) | C24: =COUNTIFS(Proyectos!$H$4:$H$60,"Luis",Proyectos!$G$4:$G$60,"Desarrollo") -> 1 | E24: Por definir | F24: =COUNTIF(Proyectos!$F$4:$F$60,"Por definir") -> 46 | H24: Avance listo para presentar | I24: =COUNTIF(Proyectos!$J$4:$J$60,"Avance listo para presentar") -> 1
B25: SIN DEV ASIGNADO (activos) | C25: =COUNTIFS(Proyectos!$H$4:$H$60,"Sin asignar",Proyectos!$G$4:$G$60,"<>Cerrado",Proyectos!$G$4:$G$60,"<>Congelado",Proyectos!$C$4:$C$60,"<>") -> 5 | H25: En revisión del cliente | I25: =COUNTIF(Proyectos!$J$4:$J$60,"En revisión del cliente") -> 0
H26: Diseño finalizado | I26: =COUNTIF(Proyectos!$J$4:$J$60,"Diseño finalizado") -> 7
B31: Qué falta cobrar
B32: Falta el 50% inicial | C32: =COUNTIF(Proyectos!$M$4:$M$60,"No") -> 0
B33: Falta el 30% de diseño | C33: =COUNTIFS(Proyectos!$G$4:$G$60,"Desarrollo",Proyectos!$N$4:$N$60,"No") -> 1
B34: Falta el 20% final | C34: =COUNTIFS(Proyectos!$G$4:$G$60,"QA + entrega",Proyectos!$O$4:$O$60,"No") -> 1
B40: Para el reporte del viernes: captura esta hoja y pégala en el correo a Luis.

Sheet Juan Carlos
A1: Proyectos — Juan Carlos
A2: Juan Carlos solo recibe proyectos en GRUPO A (50% pagado + material de diseño completo). Ordenado por la cola de prioridad de diseño; los que no tienen número van al final. No incluye cerrados, congelados, ni los que siguen en grupo B o C.
A3: SOLO EDITAS LAS 3 ÚLTIMAS COLUMNAS, las amarillas del final (P, Q y R): «Avance de diseño» (lista desplegable), «Nota de diseño» y «Fecha». Lo que pongas ahí aparece automáticamente en la hoja PROYECTOS. La columna Cliente queda fija al desplazarte a la derecha. Todo lo demás es gris: se lee solo desde PROYECTOS.
